Workbook

Sheet Assumptions
B2: Advertised price of building (SEK) | C2: 9700000
B3: Transaction year | C3: 2024
B5: Tenant | C5: Type of premise | D5: Space Occupied (m2) | E5: Lease start | F5: Lease end | G5: Start rent (SEK/m2/year) | H5: CPI adjustment (%) | I5: Fixed fraction | L5: Clients financial information
B6: Salong Kalufs | C6: Retail | D6: 95 | E6: 43831 | F6: 46752 | G6: 1950 | H6: 1 | I6: =1-H6 -> 0 | L6: Inital loan-to-value (%) | M6: 0.7
B7: Nordic Slow Fashion | C7: Retail | D7: 150 | E7: 43466 | F7: 45657 | G7: 1900 | H7: 1 | I7: =1-H7 -> 0 | L7: Price of estate (SEK) | M7: 9700000
B8: Drottningens Guldsmed | C8: Retail | D8: 60 | E8: 43466 | F8: 46022 | G8: 1900 | H8: 0.75 | I8: =1-H8 -> 0.25 | L8: Equity (%) | M8: 0.3
B9: Ärlig Redovisning Konsultbyrå | C9: Office | D9: 70 | E9: 44562 | F9: 46387 | G9: 1300 | H9: 0.75 | I9: =1-H9 -> 0.25 | L9: Interest rate (rd) (%) | M9: 0.066
B10: AI Data | C10: Office | D10: 90 | E10: 44927 | F10: 48213 | G10: 1400 | H10: 1 | I10: =1-H10 -> 0 | L10: Maturity of loan | M10: 30
B11: AMT | C11: Office | D11: 50 | E11: 44197 | F11: 47848 | G11: 1450 | H11: 1 | I11: =1-H11 -> 0
B12: Norrlands Guld | C12: Office | D12: 110 | E12: 44562 | F12: 46752 | G12: 1100 | H12: 0.75 | I12: =1-H12 -> 0.25
B13: Total Area | D13: =SUM(D6,D7,D8,D9,D10,D11,D12) -> 625
B14: Market rent for office (SEK/m2/year) | C14: 1430 | E14: O&R expected growth | F14: 0.023 | L14: Other assumptions
B15: Market rent for retail (SEK/m2/year) | C15: 1950 | E15: Nom r | F15: =(1+F14)*(1+C25)-1 -> 0.044483 | L15: Property level discount rate OCC (r)(%) | M15: 0.088
L16: Inflation rate (i) | M16: 0.021
B17: Vacancy rate (%) | C17: 0.05 | L17: Equity level discount rate (re) | M17: 0.106
L18: No tax
B19: Year | C19: Description | D19: Cost in PV (SEK)
B20: 2024 | C20: Renovation of roof space insulation | D20: 290000 | L20: Exit yield
B21: 2025 | C21: Investments to increase energy-efficency | D21: 160000 | L21: Growth rate, perpetuity (%) | M21: 0.022
B22: 2029 | C22: Renovation of facades | D22: 220000
B24: Operating costs (SEK/m2/year) | C24: 360
B25: Inflation rate (%) | C25: 0.021
B26: Year 2 | C26: 0.02
B27: Year 3 | C27: 0.03
B29: Maintenance costs (SEK/m2/year) | C29: 150
B30: Inflation rate (%) | C30: 0.021
B34: NOI | D34: =Calculation!D111 -> 691446.74 | E34: =Calculation!E111 -> 697095.45 | F34: =Calculation!F111 -> 721593.35 | G34: =Calculation!G111 -> 749861.12 | H34: =Calculation!H111 -> 816884.72 | I34: =Calculation!I111 -> 831900.09 | J34: =Calculation!J111 -> 847230.78 | K34: =Calculation!K111 -> 870215.31 | ... N34: =Calculation!N111 -> 1174487.8
B35: Salvage Value | N35: =Calculation!M116 -> 17795270
B36: PBTCF | C36: -9700000 | D36: =Calculation!D117 -> 395356.74 | E36: =Calculation!E117 -> 530304.89 | F36: =Calculation!F117 -> 721593.35 | G36: =Calculation!G117 -> 749861.12 | H36: =Calculation!H117 -> 816884.72 | I36: =Calculation!I117 -> 582683.39 | J36: =Calculation!J117 -> 847230.78 | K36: =Calculation!K117 -> 870215.31 | ... N36: =Calculation!N117 -> 0
B37: Sum of PV PBTCF | C37: =Calculation!C120 -> 12192313
B38: NPVp | C38: =Calculation!C121 -> 2492312.9
B41: =C38 -> 2492312.9 | C41: 0.01 | D41: 0.022 | E41: 0.03 | G41: =C38 -> 2492312.9 | H41: 1300 | I41: 1430 | J41: 1700
B42: 0.06 | C42: 8654267.3 | D42: 12796338 | E42: 17398639 | G42: 1700 | H42: 853839.56 | I42: 1372660 | J42: 2450210.1
B43: 0.088 | C43: 1314429.6 | D43: 2492312.9 | E43: 3548346.2 | G43: 1950 | H43: 1973492.5 | I43: 2492312.9 | J43: 3569863
B44: 0.11 | C44: -1487357.5 | D44: -923307.87 | E44: -453266.54 | G44: 2100 | H44: 2645284.3 | I44: 3164104.7 | J44: 4241654.8
B47: =C38 -> 2492312.9 | C47: 0.01 | D47: 0.02 | E47: 0.03
B48: 0.02 | C48: 2434301.5 | D48: 2464257.6 | E48: 2494213.7
B49: 0.03 | C49: 2462643.1 | D49: 2492312.9 | E49: 2521982.7
B50: 0.04 | C50: 2490984.7 | D50: 2520368.3 | E50: 2549751.8
L59: =(K4*Assumptions!D10*Assumptions!I10) -> 0
...

Sheet Calculation
C1: 2023 | D1: 2024 | E1: =D1+1 -> 2025 | F1: =E1+1 -> 2026 | G1: =F1+1 -> 2027 | H1: =G1+1 -> 2028 | I1: =H1+1 -> 2029 | J1: =I1+1 -> 2030 | K1: =J1+1 -> 2031 | L1: =K1+1 -> 2032 | M1: =L1+1 -> 2033 | N1: 2034
D2: 1 | E2: 2 | F2: 3 | G2: 4 | H2: 5 | I2: 6 | J2: 7 | K2: 8 | L2: 9 | M2: 10 | N2: 11
B4: Market Rent for Office | D4: =Assumptions!C14 -> 1430 | E4: =$D4*(1+Assumptions!$F15)^Calculation!D2 -> 1493.6107 | F4: =$D4*(1+Assumptions!$F15)^Calculation!E2 -> 1560.051 | G4: =$D4*(1+Assumptions!$F15)^Calculation!F2 -> 1629.4467 | H4: =$D4*(1+Assumptions!$F15)^Calculation!G2 -> 1701.9294 | I4: =$D4*(1+Assumptions!$F15)^Calculation!H2 -> 1777.6363 | J4: =$D4*(1+Assumptions!$F15)^Calculation!I2 -> 1856.7109 | K4: =$D4*(1+Assumptions!$F15)^Calculation!J2 -> 1939.303 | L4: =$D4*(1+Assumptions!$F15)^Calculation!K2 -> 2025.569 | ... N4: =$D4*(1+Assumptions!$F15)^Calculation!M2 -> 2209.7839
B5: Market Rent for Retail | D5: =Assumptions!C15 -> 1950 | E5: =$D5*(1+Assumptions!$F15)^Calculation!D2 -> 2036.7418 | F5: =$D5*(1+Assumptions!$F15)^Calculation!E2 -> 2127.3422 | G5: =$D5*(1+Assumptions!$F15)^Calculation!F2 -> 2221.9728 | H5: =$D5*(1+Assumptions!$F15)^Calculation!G2 -> 2320.8128 | I5: =$D5*(1+Assumptions!$F15)^Calculation!H2 -> 2424.0495 | J5: =$D5*(1+Assumptions!$F15)^Calculation!I2 -> 2531.8785 | K5: =$D5*(1+Assumptions!$F15)^Calculation!J2 -> 2644.5041 | L5: =$D5*(1+Assumptions!$F15)^Calculation!K2 -> 2762.1396 | ... N5: =$D5*(1+Assumptions!$F15)^Calculation!M2 -> 3013.3416
B7: Salong Kalufs
B8: Years Since Lease Start | D8: 4 | E8: 5 | F8: 6 | G8: 7 | H8: 8 | I8: 9 | J8: 10 | K8: 11 | L8: 12 | M8: 13
B9: Contract Rent
B10: Fixed Fraction | D10: =(Assumptions!$D6*Assumptions!$G6)*Assumptions!$I6 -> 0 | E10: =(Assumptions!$D6*Assumptions!$G6)*Assumptions!$I6 -> 0 | F10: =(Assumptions!$D6*Assumptions!$G6)*Assumptions!$I6 -> 0 | G10: =(Assumptions!$D6*Assumptions!$G6)*Assumptions!$I6 -> 0
B11: CPI Adjustment | D11: =(Assumptions!G6*Assumptions!D6)*Assumptions!H6*(1+Assumptions!C25)^Calculation!D8 -> 201308.07 | E11: =(Assumptions!$G6*Assumptions!$D6)*Assumptions!$H6*(1+Assumptions!$C25)^Calculation!E8 -> 205535.54 | F11: =(Assumptions!$G6*Assumptions!$D6)*Assumptions!$H6*(1+Assumptions!$C25)^Calculation!F8 -> 209851.79 | G11: =(Assumptions!$G6*Assumptions!$D6)*Assumptions!$H6*(1+Assumptions!$C25)^Calculation!G8 -> 214258.67
B12: Rent During Contract Time | D12: =D10+D11 -> 201308.07 | E12: =E10+E11 -> 205535.54 | F12: =F10+F11 -> 209851.79 | G12: =G10+G11 -> 214258.67
B13: Rent After Renewal of Contract | H13: =($H5*Assumptions!$D6) -> 220477.22 | N13: =(N5*Assumptions!D6) -> 286267.45
B14: Fixed Fraction | I14: =($H5*Assumptions!$D6)*Assumptions!$I6 -> 0 | J14: =($H5*Assumptions!$D6)*Assumptions!$I6 -> 0 | K14: =($H5*Assumptions!$D6)*Assumptions!$I6 -> 0 | L14: =($H5*Assumptions!$D6)*Assumptions!$I6 -> 0 | M14: =($H5*Assumptions!$D6)*Assumptions!$I6 -> 0
B15: CPI Adjustment | I15: =($H5*Assumptions!$D6)*Assumptions!$H6*(1+Assumptions!$C25)^D2 -> 225107.24 | J15: =($H5*Assumptions!$D6)*Assumptions!$H6*(1+Assumptions!$C25)^E2 -> 229834.49 | K15: =($H5*Assumptions!$D6)*Assumptions!$H6*(1+Assumptions!$C25)^F2 -> 234661.02 | L15: =($H5*Assumptions!$D6)*Assumptions!$H6*(1+Assumptions!$C25)^G2 -> 239588.9 | M15: =($H5*Assumptions!$D6)*Assumptions!$H6*(1+Assumptions!$C25)^H2 -> 244620.26
B16: Rent During Contract Time | I16: =I14+I15 -> 225107.24 | J16: =J14+J15 -> 229834.49 | K16: =K14+K15 -> 234661.02 | L16: =L14+L15 -> 239588.9 | M16: =M14+M15 -> 244620.26
B17: Annual Rent | D17: =D12 -> 201308.07 | E17: =E12 -> 205535.54 | F17: =F12 -> 209851.79 | G17: =G12 -> 214258.67 | H17: =H13 -> 220477.22 | I17: =I16 -> 225107.24 | J17: =J16 -> 229834.49 | K17: =K16 -> 234661.02 | L17: =L16 -> 239588.9 | M17: =M16 -> 244620.26 | N17: =N13 -> 286267.45
B19: Nordic Slow Fashion
B20: Years Since Lease Start | D20: 5 | E20: 6 | F20: 7 | G20: 8 | H20: 9 | I20: 10 | J20: 11 | K20: 12 | L20: 13 | M20: 14
B21: Contract Rent
B22: Fixed Fraction | D22: =Assumptions!$D7*Assumptions!$G7*Assumptions!$I7 -> 0
B23: CPI Adjustment | D23: =(Assumptions!D7*Assumptions!G7*Assumptions!H7)*(1+Assumptions!C25)^Calculation!D20 -> 316208.52
B24: Rent during contract time | D24: =D22+D23 -> 316208.52 | E24: =Calculation!D109 -> 225000
B25: Rent after renewal of contract | E25: =($E5*Assumptions!$D7) -> 305511.28 | N25: =N5*Assumptions!D7 -> 452001.24
B26: Fixed fraction | F26: =($E5*Assumptions!$D7*Assumptions!$I7) -> 0 | G26: =($E5*Assumptions!$D7*Assumptions!$I7) -> 0 | H26: =($E5*Assumptions!$D7*Assumptions!$I7) -> 0 | I26: =($E5*Assumptions!$D7*Assumptions!$I7) -> 0 | J26: =($E5*Assumptions!$D7*Assumptions!$I7) -> 0 | K26: =($E5*Assumptions!$D7*Assumptions!$I7) -> 0 | L26: =($E5*Assumptions!$D7*Assumptions!$I7) -> 0 | M26: =($E5*Assumptions!$D7*Assumptions!$I7) -> 0
B27: CPI Adjustment | F27: =(Calculation!$E5*Assumptions!$D7*Assumptions!$H7)*(1+Assumptions!$C25)^Calculation!D2 -> 311927.01 | G27: =(Calculation!$E5*Assumptions!$D7*Assumptions!$H7)*(1+Assumptions!$C25)^Calculation!E2 -> 318477.48 | H27: =(Calculation!$E5*Assumptions!$D7*Assumptions!$H7)*(1+Assumptions!$C25)^Calculation!F2 -> 325165.51 | I27: =(Calculation!$E5*Assumptions!$D7*Assumptions!$H7)*(1+Assumptions!$C25)^Calculation!G2 -> 331993.98 | J27: =(Calculation!$E5*Assumptions!$D7*Assumptions!$H7)*(1+Assumptions!$C25)^Calculation!H2 -> 338965.86 | K27: =(Calculation!$E5*Assumptions!$D7*Assumptions!$H7)*(1+Assumptions!$C25)^Calculation!I2 -> 346084.14 | L27: =(Calculation!$E5*Assumptions!$D7*Assumptions!$H7)*(1+Assumptions!$C25)^Calculation!J2 -> 353351.91 | M27: =(Calculation!$E5*Assumptions!$D7*Assumptions!$H7)*(1+Assumptions!$C25)^Calculation!K2 -> 360772.3
B28: Rent during contract time | F28: =F26+F27 -> 311927.01 | G28: =G26+G27 -> 318477.48 | H28: =H26+H27 -> 325165.51 | I28: =I26+I27 -> 331993.98 | J28: =J26+J27 -> 338965.86 | K28: =K26+K27 -> 346084.14 | L28: =L26+L27 -> 353351.91 | M28: =M26+M27 -> 360772.3
B29: Annual rent | D29: =D23 -> 316208.52 | E29: =E25 -> 305511.28 | F29: =F27 -> 311927.01 | G29: =G27 -> 318477.48 | H29: =H27 -> 325165.51 | I29: =I27 -> 331993.98 | J29: =J27 -> 338965.86 | K29: =K27 -> 346084.14 | L29: =L27 -> 353351.91 | M29: =M27 -> 360772.3 | N29: =N25 -> 452001.24
B31: Drottningens Guldsmed
B32: Years since lease start | D32: 5 | E32: 6 | F32: 7 | G32: 8 | H32: 9 | I32: 10 | J32: 11 | K32: 12 | L32: 13 | M32: 14
B33: Contract rent
B34: Fixed fraction | D34: =(Assumptions!$D8*Assumptions!$G8)*Assumptions!$I8 -> 28500 | E34: =(Assumptions!$D8*Assumptions!$G8)*Assumptions!$I8 -> 28500
B35: CPI adjustment | D35: =(Assumptions!$D8*Assumptions!$G8)*Assumptions!$H8*(1+Assumptions!$C25)^Calculation!D32 -> 94862.557 | E35: =(Assumptions!$D8*Assumptions!$G8)*Assumptions!$H8*(1+Assumptions!$C25)^Calculation!E32 -> 96854.67
B36: Rent during contract time | D36: =D34+D35 -> 123362.56 | E36: =E34+E35 -> 125354.67
B37: Rent after renewal of contract | F37: =($F5*Assumptions!$D8) -> 127640.53 | N37: =N5*Assumptions!D8 -> 180800.5
B38: Fixed fraction | G38: =($F5*Assumptions!$D8)*Assumptions!$I8 -> 31910.134 | H38: =($F5*Assumptions!$D8)*Assumptions!$I8 -> 31910.134 | I38: =($F5*Assumptions!$D8)*Assumptions!$I8 -> 31910.134 | J38: =($F5*Assumptions!$D8)*Assumptions!$I8 -> 31910.134 | K38: =($F5*Assumptions!$D8)*Assumptions!$I8 -> 31910.134 | L38: =($F5*Assumptions!$D8)*Assumptions!$I8 -> 31910.134 | M38: =($F5*Assumptions!$D8)*Assumptions!$I8 -> 31910.134
B39: CPI Adjustment | G39: =($F5*Assumptions!$D8)*Assumptions!$H8*(1+Assumptions!$C25)^D2 -> 97740.739 | H39: =($F5*Assumptions!$D8)*Assumptions!$H8*(1+Assumptions!$C25)^E2 -> 99793.295 | I39: =($F5*Assumptions!$D8)*Assumptions!$H8*(1+Assumptions!$C25)^F2 -> 101888.95 | J39: =($F5*Assumptions!$D8)*Assumptions!$H8*(1+Assumptions!$C25)^G2 -> 104028.62 | K39: =($F5*Assumptions!$D8)*Assumptions!$H8*(1+Assumptions!$C25)^H2 -> 106213.22 | L39: =($F5*Assumptions!$D8)*Assumptions!$H8*(1+Assumptions!$C25)^I2 -> 108443.7 | M39: =($F5*Assumptions!$D8)*Assumptions!$H8*(1+Assumptions!$C25)^J2 -> 110721.02
B40: Rent during contract time | G40: =G38+G39 -> 129650.87 | H40: =H38+H39 -> 131703.43 | I40: =I38+I39 -> 133799.09 | J40: =J38+J39 -> 135938.76 | K40: =K38+K39 -> 138123.36 | L40: =L38+L39 -> 140353.83 | M40: =M38+M39 -> 142631.15
B41: Annual rent | D41: =D36 -> 123362.56 | E41: =E36 -> 125354.67 | F41: =F37 -> 127640.53 | G41: =G40 -> 129650.87 | H41: =H40 -> 131703.43 | I41: =I40 -> 133799.09 | J41: =J40 -> 135938.76 | K41: =K40 -> 138123.36 | L41: =L40 -> 140353.83 | M41: =M40 -> 142631.15 | N41: =N37 -> 180800.5
B43: Ärlig Redovisning Konsultbyrå
B44: Years since lease start | D44: 2 | E44: 3 | F44: 4 | G44: 5 | H44: 6 | I44: 7 | J44: 8 | K44: 9 | L44: 10 | M44: 11
B45: Contract rent
...

Sheet Results
B2: Rubrik | C2: SEK | D2: SEK/m2 | E2: IRR(%)
B3: Property Before-Tax Cash Flow PV | C3: =Calculation!C120 -> 12192313 | D3: =C3/Assumptions!D13 -> 19507.701
B4: Property Before-Tax Cash Flow NPV | C4: =Calculation!C121 -> 2492312.9 | D4: =C4/Assumptions!D13 -> 3987.7007
B5: Equity Before-Tax Cash Flow NPVe | C5: =Calculation!C147 -> 2498747.8 | D5: =C5/Assumptions!D13 -> 3997.9964
B6: Property Before-Tax Cash Flow IRR | E6: =Calculation!C122 -> 0.11883794
B7: Equity Before-Tax Cash Flow IRRe | E7: =Calculation!C148 -> 0.18122673
B9: Property level discount rate
B10: =Assumptions!B41 -> 2492312.9 | C10: 0.01 | D10: 0.022 | E10: 0.03
B11: 0.06 | C11: 8654267.3 | D11: 12796338 | E11: 17398639
B12: 0.088 | C12: 1314429.6 | D12: 2492312.9 | E12: 3548346.2
B13: 0.11 | C13: -1487357.5 | D13: -923307.87 | E13: -453266.54
B15: Office and retail rent
B16: =Assumptions!B41 -> 2492312.9 | C16: 0.01 | D16: 0.02 | E16: 0.03
B17: 0.02 | C17: 2434301.5 | D17: 2464257.6 | E17: 2494213.7
B18: 0.03 | C18: 2462643.1 | D18: 2492312.9 | E18: 2521982.7
B19: 0.04 | C19: 2490984.7 | D19: 2520368.3 | E19: 2549751.8
B21: Change in operating costs after CAPEX 1 and CAPEX 2
B22: =Assumptions!B41 -> 2492312.9 | C22: 1300 | D22: 1430 | E22: 1700
B23: 1700 | C23: 853839.56 | D23: 1372660 | E23: 2450210.1
B24: 1950 | C24: 1973492.5 | D24: 2492312.9 | E24: 3569863
B25: 2100 | C25: 2645284.3 | D25: 3164104.7 | E25: 4241654.8
B29: Value of property level | G29: 1. Based on the property level NPV and IRR, should your client buy the property?
B30: Sum of PV PBTCF | C30: =Calculation!C120 -> 12192313 | G30: Yes. That is since the NPV value is bigger than 0, and the IRR is higher than property level discount rate.
B31: NPVp | C31: =Calculation!C121 -> 2492312.9
B32: IRRp | C32: =Calculation!C122 -> 0.11883794 | G32: 2. Based on the given financing assumptions, what are the NPVe and IRRe ?
F33: NPVe | G33: =C36 -> 2498747.8
B34: Value of equity level | F34: IRRe | G34: =C37 -> 0.18122673
B35: Sum of PV EBTCF | C35: =Calculation!C146 -> 5408747.8
B36: NPVe | C36: =Calculation!C147 -> 2498747.8 | G36: 3. What is the maximum amount of money your client should pay for this property (i.e. what is the investment value)?
B37: IRRe | C37: =Calculation!C148 -> 0.18122673 | F37: Maximum amount | G37: =C30 -> 12192313
